Workbook

Sheet S2R Review
A1: bug_id | B1: app_name | C1: agent_version | D1: description_level | E1: description_text | F1: full_bug_report | G1: s2r_gt | H1: agent_generated_steps | I1: LLM_evaluation | J1: Matched_GT_by_LLM | K1: human_evaluation | L1: Precision | M1: Recall | N1: F1 | O1: GT Step Count
A2: 135 | B2: Wikimedia Commons | C2: bugscribe_mutli-candidate_transitions_and_screen_descriptions | D2: HC_HP | E2: Open App, swipe left four times, tap YES, tap Skip, tap YES, open the navigation drawer, select Explore, tap a picture, swipe up twice, tap a category, and tap Parent Categories to reach the Category screen in the Parent Categories tab; clicking the Parent Categories tab results in a blank page, but the Parent Categories of the current category should be displayed. | F2: Title: Parent Categories tab opens a blank page on the category details screen Observed Behavior: On the category details screen, if the user taps the Parent Categories tab, a blank page is shown. Expected Behavior: The Parent Categories of the current category should be displayed. | G2: 1. Open App <8e8c7133a537849ea1f09bcc2625161404e90d5f93d33e01c0e90230c92a5a7a> 2. Swipe Left <b3d177434c01973aefd635e9b2c077d1ba46bf4e2a80da4ed89474511160b63d> 3. Swipe Left <e0f12adac56be76acb79d37d0e90aa329ca9de72ca3481f451a5311f141027c4> 4. Swipe Left <8816181fdd2f34a86b06a3bc7208d741eee74c5da62d980f09630d2cf47f6df1> 5. Swipe Left <b71f779a1f0963d53f1859ce1784a17f4a319592a660124b62c8f18a53cf46e8> 6. Click YES <9637973e88b508b265333dbf56463d16981017c2c09b4c69c5b9902e347d39e5> 7. Click Skip <bb009cd969fdfffc3f5842081f292334289f80d5b8fc399d1fce7ec4972173c4> 8. Click YES <a15358162dfdc9d6068f688c1a95276f63e1788b93f9311047afa58f7e695b0b> 9. Click the navigation drawer button, i.e., the menu option <1d89fc61d139df7152892234c2a3f5174669a9b3b57a90c88ff95b811528ce5e> 10. Click Explore <2cb54b6b2c319fadcb77770ddc6f08bc1620d2ea99af5e4315a0e04d97476e34> 11. Click a picture <eeb2dcc5b038a5365fc5e3968862c3ae476f8c007955b49e9585b8a8b05bc0c1> 12. Swipe Up <d84994fbe18eaf7d76f1dfe454496f07db5e6a0c2213452558c14661322567ac> 13. Swipe Up <44efd4db46c1a856f86f5f10423f5a596b37a4499b0d7f8dbc4036eba4edddf7> 14. Click a category <f855240a7c5488e1a1fd483c6fec3b99757ca2940f7ceba50517a42c5e6211dc> 15. Click parent Categories <31951cb9f29b46f435d8f75ccd1b6f6cc6ead9febe61faa81dad6e547e91a68f> | H2: Open the app. <8e8c7133a537849ea1f09bcc2625161404e90d5f93d33e01c0e90230c92a5a7a> | I2: CS | J2: Open App <8e8c7133a537849ea1f09bcc2625161404e90d5f93d33e01c0e90230c92a5a7a> | K2: CS | L2: =IFERROR(COUNTIF(K2:K16,"CS")/COUNTA(K2:K16),"") | M2: =COUNTIF(K2:K16,"CS")/15 | N2: =IFERROR(2*(L2*M2)/(L2+M2),"") | O2: 15
H3: Swipe left on the welcome/tutorial screen. <b3d177434c01973aefd635e9b2c077d1ba46bf4e2a80da4ed89474511160b63d> | I3: CS | J3: Swipe Left <b3d177434c01973aefd635e9b2c077d1ba46bf4e2a80da4ed89474511160b63d> | K3: CS
H4: Swipe left again on the welcome/tutorial screen. <e0f12adac56be76acb79d37d0e90aa329ca9de72ca3481f451a5311f141027c4> | I4: CS | J4: Swipe Left <e0f12adac56be76acb79d37d0e90aa329ca9de72ca3481f451a5311f141027c4> | K4: CS
H5: Swipe left a third time on the welcome/tutorial screen. <8816181fdd2f34a86b06a3bc7208d741eee74c5da62d980f09630d2cf47f6df1> | I5: CS | J5: Swipe Left <8816181fdd2f34a86b06a3bc7208d741eee74c5da62d980f09630d2cf47f6df1> | K5: CS
H6: Swipe left a fourth time on the welcome/tutorial screen. <b71f779a1f0963d53f1859ce1784a17f4a319592a660124b62c8f18a53cf46e8> | I6: CS | J6: Swipe Left <b71f779a1f0963d53f1859ce1784a17f4a319592a660124b62c8f18a53cf46e8> | K6: CS
H7: Tap "YES!" on the final welcome screen. <9637973e88b508b265333dbf56463d16981017c2c09b4c69c5b9902e347d39e5> | I7: CS | J7: Click YES <9637973e88b508b265333dbf56463d16981017c2c09b4c69c5b9902e347d39e5> | K7: CS
H8: Tap "Skip" on the login screen. <bb009cd969fdfffc3f5842081f292334289f80d5b8fc399d1fce7ec4972173c4> | I8: CS | J8: Click Skip <bb009cd969fdfffc3f5842081f292334289f80d5b8fc399d1fce7ec4972173c4> | K8: CS
H9: Confirm skipping login by tapping "YES". <a15358162dfdc9d6068f688c1a95276f63e1788b93f9311047afa58f7e695b0b> | I9: CS | J9: Click YES <a15358162dfdc9d6068f688c1a95276f63e1788b93f9311047afa58f7e695b0b> | K9: CS
H10: Open the navigation drawer from the Explore screen. <1d89fc61d139df7152892234c2a3f5174669a9b3b57a90c88ff95b811528ce5e> | I10: CS | J10: Click the navigation drawer button, i.e., the menu option <1d89fc61d139df7152892234c2a3f5174669a9b3b57a90c88ff95b811528ce5e> | K10: CS
H11: Select "Explore" from the navigation drawer. <2cb54b6b2c319fadcb77770ddc6f08bc1620d2ea99af5e4315a0e04d97476e34> | I11: CS | J11: Click Explore <2cb54b6b2c319fadcb77770ddc6f08bc1620d2ea99af5e4315a0e04d97476e34> | K11: CS
H12: Tap a picture in Explore. <eeb2dcc5b038a5365fc5e3968862c3ae476f8c007955b49e9585b8a8b05bc0c1> | I12: CS | J12: Click a picture <eeb2dcc5b038a5365fc5e3968862c3ae476f8c007955b49e9585b8a8b05bc0c1> | K12: CS
H13: Swipe up on the media details screen. <d84994fbe18eaf7d76f1dfe454496f07db5e6a0c2213452558c14661322567ac> | I13: CS | J13: Swipe Up <d84994fbe18eaf7d76f1dfe454496f07db5e6a0c2213452558c14661322567ac> | K13: CS
H14: Swipe up again on the media details screen. <44efd4db46c1a856f86f5f10423f5a596b37a4499b0d7f8dbc4036eba4edddf7> | I14: CS | J14: Swipe Up <44efd4db46c1a856f86f5f10423f5a596b37a4499b0d7f8dbc4036eba4edddf7> | K14: CS
... H16: Tap the "PARENT CATEGORIES" tab. <31951cb9f29b46f435d8f75ccd1b6f6cc6ead9febe61faa81dad6e547e91a68f> | I16: CS | J16: Click parent Categories <31951cb9f29b46f435d8f75ccd1b6f6cc6ead9febe61faa81dad6e547e91a68f> | K16: CS
A18: 2 | B18: Family Finance | C18: bugscribe_mutli-candidate_transitions_and_screen_descriptions | D18: HC_HP | E18: On Display of Incomes by Articles pop-up of the Reports screen changing the report appearance from 'view values' to 'use percent values' causes the application to crash, but the appearance of the report should be changed to 'use percent values'. I took these steps: Open the app, tap Allow, select Report, choose Incomes By Articles or Expenses By Articles, tap View, check 'view values', check 'use percent values', and tap OK. | F18: Title: App crashes when applying both View values and Use percent values in the Display of Incomes by Articles dialog Observed Behavior: On the Display of Incomes by Articles pop-up of the Reports screen, if the user checks View values, checks Use percent values, and taps OK, the application crashes. Expected Behavior: The appearance of the report should be changed to use percent values. | G18: 1. Open app <fa8baa4de2d1015dd5da60a38bcc25a725e918d25bafb6b4b8bafe8f727ccfcf> 2. Click allow button <8407e328c4a9d75304cf3edee19af6616ae654caca4e79229e0df0c827909816> 3. Click Report <9a4f389ec16dc06bc51519fd35159ab49c667d2cae3e0323df9bf08cd98bda88 4. Click Incomes By Articles or expenses by articles <c010db1badf9deb0564b10c46916ad505c7d1acca0f840fdc12c4867c81990d0> 5. Click View Button <c7c181b4d07f85b6731edefa0c51eca8637b088e992c8d07e2349379db3cd413> 6. Click view values checkbox <dc01c666d81db01f9ceb751ff256033bcc27f75ab0951ef2f9eff49e39233d64> 7. Click use percent values checkbox <c3292f1abb084883da9f0bf06776dd33343b186505d53bedfbb8b83717e4b319> 8. Click OK <26c0ae2d76021672cf80c07928394773aec07f5be831f91ab09b5f7c2392b6aa> | H18: Open the app. <fa8baa4de2d1015dd5da60a38bcc25a725e918d25bafb6b4b8bafe8f727ccfcf> | I18: CS | J18: Open app <fa8baa4de2d1015dd5da60a38bcc25a725e918d25bafb6b4b8bafe8f727ccfcf> | K18: CS | L18: =IFERROR(COUNTIF(K18:K25,"CS")/COUNTA(K18:K25),"") | M18: =COUNTIF(K18:K25,"CS")/8 | N18: =IFERROR(2*(L18*M18)/(L18+M18),"") | O18: 8
H19: Tap Allow on the SMS permission dialog. <8407e328c4a9d75304cf3edee19af6616ae654caca4e79229e0df0c827909816> | I19: CS | J19: Click allow button <8407e328c4a9d75304cf3edee19af6616ae654caca4e79229e0df0c827909816> | K19: CS
H20: Tap Reports from the main screen. <9a4f389ec16dc06bc51519fd35159ab49c667d2cae3e0323df9bf08cd98bda88> | I20: CS | J20: Click Report <9a4f389ec16dc06bc51519fd35159ab49c667d2cae3e0323df9bf08cd98bda88 | K20: CS
H21: Select Incomes by Articles. <c010db1badf9deb0564b10c46916ad505c7d1acca0f840fdc12c4867c81990d0> | I21: CS | J21: Click Incomes By Articles or expenses by articles <c010db1badf9deb0564b10c46916ad505c7d1acca0f840fdc12c4867c81990d0> | K21: CS
H22: Tap Display to open the Display of Incomes by Articles dialog. <c7c181b4d07f85b6731edefa0c51eca8637b088e992c8d07e2349379db3cd413> | I22: CS | J22: Click View Button <c7c181b4d07f85b6731edefa0c51eca8637b088e992c8d07e2349379db3cd413> | K22: CS
H23: Check View values. <dc01c666d81db01f9ceb751ff256033bcc27f75ab0951ef2f9eff49e39233d64> | I23: CS | J23: Click view values checkbox <dc01c666d81db01f9ceb751ff256033bcc27f75ab0951ef2f9eff49e39233d64> | K23: CS
H24: Check Use percent values. <c3292f1abb084883da9f0bf06776dd33343b186505d53bedfbb8b83717e4b319> | I24: CS | J24: Click use percent values checkbox <c3292f1abb084883da9f0bf06776dd33343b186505d53bedfbb8b83717e4b319> | K24: CS
H25: Tap OK. <26c0ae2d76021672cf80c07928394773aec07f5be831f91ab09b5f7c2392b6aa> | I25: CS | J25: Click OK <26c0ae2d76021672cf80c07928394773aec07f5be831f91ab09b5f7c2392b6aa> | K25: CS
A27: 10 | B27: Material Files | C27: bugscribe_mutli-candidate_transitions_and_screen_descriptions | D27: HC_LP | E27: On the FTP server screen, stopping it and closing the app makes the server restart, even though it should stay stopped. | G27: 1. Open app <aa09f6aef3409759f67d672c9efcbd64d8f3b0ee61cf3e8d197f0539e34430d2> 2. Click allow <9253ef287211a96261d15d2522d1499f880b411f5e49851b98bae34f3403ab9d> 3. Click the navigation drawer button, i.e., the menu option <3abd760d81519f7d0b2fe5daa74c918b40f9496bef2bf776dd7b0d8e95a47b49> 4. Click FTP server <ed4ddd149d2da1bda9c6a957048313602988bce3f183bd199efeacece662aeec> 5. Click the status toggle button (switch server on) <8453ee6186ad267c55c0f443ad2d1644911453cf4f005a06837b415345db6be5 > 6. Click the status toggle button (switch server off) <5f369cd30bd1e5644d294c31e5ff58277cad40b2633f69cc4105944721df8b1b> | H27: Open the app. <aa09f6aef3409759f67d672c9efcbd64d8f3b0ee61cf3e8d197f0539e34430d2> | I27: CS | J27: Open app <aa09f6aef3409759f67d672c9efcbd64d8f3b0ee61cf3e8d197f0539e34430d2> | K27: CS | L27: =IFERROR(COUNTIF(K27:K32,"CS")/COUNTA(K27:K32),"") | M27: =COUNTIF(K27:K32,"CS")/6 | N27: =IFERROR(2*(L27*M27)/(L27+M27),"") | O27: 6
H28: Grant the storage permission by tapping Allow. <9253ef287211a96261d15d2522d1499f880b411f5e49851b98bae34f3403ab9d> | I28: CS | J28: Click allow <9253ef287211a96261d15d2522d1499f880b411f5e49851b98bae34f3403ab9d> | K28: CS
H29: Open the navigation drawer from the main Files screen. <3abd760d81519f7d0b2fe5daa74c918b40f9496bef2bf776dd7b0d8e95a47b49> | I29: CS | J29: Click the navigation drawer button, i.e., the menu option <3abd760d81519f7d0b2fe5daa74c918b40f9496bef2bf776dd7b0d8e95a47b49> | K29: CS
H30: Select FTP server from the navigation drawer. <ed4ddd149d2da1bda9c6a957048313602988bce3f183bd199efeacece662aeec> | I30: CS | J30: Click FTP server <ed4ddd149d2da1bda9c6a957048313602988bce3f183bd199efeacece662aeec> | K30: CS
H31: On the FTP server screen, tap the ON switch to stop the FTP server. <8453ee6186ad267c55c0f443ad2d1644911453cf4f005a06837b415345db6be5> | I31: CS | J31: Click the status toggle button (switch server on) <8453ee6186ad267c55c0f443ad2d1644911453cf4f005a06837b415345db6be5 > | K31: CS
H32: Close the app by pressing Back from the FTP server screen. <944abf1e97748f2436418aea5aa65a35e80ea307f807f0264ae85d2c80188e7c> | I32: ES | K32: ES
A34: 10 | B34: Material Files | C34: bugscribe_mutli-candidate_transitions_and_screen_descriptions | D34: LC_LP | E34: It restarts on its own. | G34: 1. Open app <aa09f6aef3409759f67d672c9efcbd64d8f3b0ee61cf3e8d197f0539e34430d2> 2. Click allow <9253ef287211a96261d15d2522d1499f880b411f5e49851b98bae34f3403ab9d> 3. Click the navigation drawer button, i.e., the menu option <3abd760d81519f7d0b2fe5daa74c918b40f9496bef2bf776dd7b0d8e95a47b49> 4. Click FTP server <ed4ddd149d2da1bda9c6a957048313602988bce3f183bd199efeacece662aeec> 5. Click the status toggle button (switch server on) <8453ee6186ad267c55c0f443ad2d1644911453cf4f005a06837b415345db6be5 > 6. Click the status toggle button (switch server off) <5f369cd30bd1e5644d294c31e5ff58277cad40b2633f69cc4105944721df8b1b> | H34: Open the app. <aa09f6aef3409759f67d672c9efcbd64d8f3b0ee61cf3e8d197f0539e34430d2> | I34: CS | J34: Open app <aa09f6aef3409759f67d672c9efcbd64d8f3b0ee61cf3e8d197f0539e34430d2> | K34: CS | L34: =IFERROR(COUNTIF(K34:K43,"CS")/COUNTA(K34:K43),"") | M34: =COUNTIF(K34:K43,"CS")/6 | N34: =IFERROR(2*(L34*M34)/(L34+M34),"") | O34: 6
H35: On the permission dialog, tap Allow. <9253ef287211a96261d15d2522d1499f880b411f5e49851b98bae34f3403ab9d> | I35: CS | J35: Click allow <9253ef287211a96261d15d2522d1499f880b411f5e49851b98bae34f3403ab9d> | K35: CS
H36: Open the navigation menu by tapping Navigate up. <3abd760d81519f7d0b2fe5daa74c918b40f9496bef2bf776dd7b0d8e95a47b49> | I36: CS | J36: Click the navigation drawer button, i.e., the menu option <3abd760d81519f7d0b2fe5daa74c918b40f9496bef2bf776dd7b0d8e95a47b49> | K36: CS
H37: Select FTP server from the navigation drawer. <ed4ddd149d2da1bda9c6a957048313602988bce3f183bd199efeacece662aeec> | I37: CS | J37: Click FTP server <ed4ddd149d2da1bda9c6a957048313602988bce3f183bd199efeacece662aeec> | K37: CS
H38: Tap the FTP server status switch while it is OFF to turn it ON. <5f369cd30bd1e5644d294c31e5ff58277cad40b2633f69cc4105944721df8b1b> | I38: CS | J38: Click the status toggle button (switch server off) <5f369cd30bd1e5644d294c31e5ff58277cad40b2633f69cc4105944721df8b1b> | K38: CS
H39: Tap the FTP server status switch while it is ON to turn it OFF. <8453ee6186ad267c55c0f443ad2d1644911453cf4f005a06837b415345db6be5> | I39: CS | J39: Click the status toggle button (switch server on) <8453ee6186ad267c55c0f443ad2d1644911453cf4f005a06837b415345db6be5 > | K39: CS
H40: Leave the FTP server screen by tapping Navigate up. <f5deb5a7a067fcecd183ba802aa26e2dfb3c5e38306d9407fd3b178866210afb> | I40: ES | K40: ES
H41: Tap the list item to return to the FTP server screen path context. <6766d1c12b54808176b7d8e110b78ee25e2843492f806acedcc0d8e1da70972c> | I41: ES | K41: ES
H42: Open Recents using the system Back/Recents control. <944abf1e97748f2436418aea5aa65a35e80ea307f807f0264ae85d2c80188e7c> | I42: ES | K42: ES
H43: Dismiss the Files app task from Recents. <b05234dc13810ef197b494fe9ce3b3d6e6927d53c722ad904f3dc53e425da84c> | I43: ES | K43: ES
A45: 135 | B45: Wikimedia Commons | C45: bugscribe_mutli-candidate_transitions_and_screen_descriptions | D45: HC_HP | E45: Open App, swipe left four times, tap YES, tap Skip, tap YES, open the navigation drawer, select Explore, tap a picture, swipe up twice, tap a category, and tap Parent Categories to reach the Category screen in the Parent Categories tab; clicking the Parent Categories tab results in a blank page, but the Parent Categories of the current category should be displayed. | F45: Title: Parent Categories tab opens a blank page on the category details screen Observed Behavior: On the Category Details screen in the Parent Categories tab, if the user taps the PARENT CATEGORIES tab, a blank page is shown. Expected Behavior: The Parent Categories of the current category should be displayed. | G45: 1. Open App <8e8c7133a537849ea1f09bcc2625161404e90d5f93d33e01c0e90230c92a5a7a> 2. Swipe Left <b3d177434c01973aefd635e9b2c077d1ba46bf4e2a80da4ed89474511160b63d> 3. Swipe Left <e0f12adac56be76acb79d37d0e90aa329ca9de72ca3481f451a5311f141027c4> 4. Swipe Left <8816181fdd2f34a86b06a3bc7208d741eee74c5da62d980f09630d2cf47f6df1> 5. Swipe Left <b71f779a1f0963d53f1859ce1784a17f4a319592a660124b62c8f18a53cf46e8> 6. Click YES <9637973e88b508b265333dbf56463d16981017c2c09b4c69c5b9902e347d39e5> 7. Click Skip <bb009cd969fdfffc3f5842081f292334289f80d5b8fc399d1fce7ec4972173c4> 8. Click YES <a15358162dfdc9d6068f688c1a95276f63e1788b93f9311047afa58f7e695b0b> 9. Click the navigation drawer button, i.e., the menu option <1d89fc61d139df7152892234c2a3f5174669a9b3b57a90c88ff95b811528ce5e> 10. Click Explore <2cb54b6b2c319fadcb77770ddc6f08bc1620d2ea99af5e4315a0e04d97476e34> 11. Click a picture <eeb2dcc5b038a5365fc5e3968862c3ae476f8c007955b49e9585b8a8b05bc0c1> 12. Swipe Up <d84994fbe18eaf7d76f1dfe454496f07db5e6a0c2213452558c14661322567ac> 13. Swipe Up <44efd4db46c1a856f86f5f10423f5a596b37a4499b0d7f8dbc4036eba4edddf7> 14. Click a category <f855240a7c5488e1a1fd483c6fec3b99757ca2940f7ceba50517a42c5e6211dc> 15. Click parent Categories <31951cb9f29b46f435d8f75ccd1b6f6cc6ead9febe61faa81dad6e547e91a68f> | H45: Open the app. <8e8c7133a537849ea1f09bcc2625161404e90d5f93d33e01c0e90230c92a5a7a> | I45: CS | J45: Open App <8e8c7133a537849ea1f09bcc2625161404e90d5f93d33e01c0e90230c92a5a7a> | K45: CS | L45: =IFERROR(COUNTIF(K45:K61,"CS")/COUNTA(K45:K61),"") | M45: =COUNTIF(K45:K61,"CS")/15 | N45: =IFERROR(2*(L45*M45)/(L45+M45),"") | O45: 15
...

Sheet Info Elements Review
A1: bug_id | B1: app_name | C1: agent_version | D1: description_level | E1: description_text | F1: full_generated_bug_report | G1: info_elements_gt | H1: agent_generated_info_elements | I1: buggy_behavior_grade | J1: triggering_gui_interactions_grade | K1: triggering_screen_reference_grade | L1: correct_behavior_grade
A2: 135 | B2: Wikimedia Commons | C2: bugscribe_mutli-candidate_transitions_and_screen_descriptions | D2: HC_HP | E2: Open App, swipe left four times, tap YES, tap Skip, tap YES, open the navigation drawer, select Explore, tap a picture, swipe up twice, tap a category, and tap Parent Categories to reach the Category screen in the Parent Categories tab; clicking the Parent Categories tab results in a blank page, but the Parent Categories of the current category should be displayed. | F2: Title: Parent Categories tab opens a blank page on the category details screen Observed Behavior: On the category details screen, if the user taps the Parent Categories tab, a blank page is shown. Expected Behavior: The Parent Categories of the current category should be displayed. | G2: Buggy Behavior: see a blank page Triggering GUI Interaction: clicks the Parent Categories tab Triggering Screen Reference: Category screen, Parent Categories tab Correct Behavior: The Parent Categories of the current category should be displayed | H2: Buggy Behavior: a blank page is shown Triggering GUI Interactions: taps the Parent Categories tab Triggering Screen Reference: On the category details screen Correct Behavior: The Parent Categories of the current category should be displayed. | I2: Correct | J2: Correct | K2: Incomplete | L2: Correct
A4: 2 | B4: Family Finance | C4: bugscribe_mutli-candidate_transitions_and_screen_descriptions | D4: HC_HP | E4: On Display of Incomes by Articles pop-up of the Reports screen changing the report appearance from 'view values' to 'use percent values' causes the application to crash, but the appearance of the report should be changed to 'use percent values'. I took these steps: Open the app, tap Allow, select Report, choose Incomes By Articles or Expenses By Articles, tap View, check 'view values', check 'use percent values', and tap OK. | F4: Title: App crashes when applying both View values and Use percent values in the Display of Incomes by Articles dialog Observed Behavior: On the Display of Incomes by Articles pop-up of the Reports screen, if the user checks View values, checks Use percent values, and taps OK, the application crashes. Expected Behavior: The appearance of the report should be changed to use percent values. | G4: Buggy Behavior: the application crashes Triggering GUI Interaction: changes the appearance of the report from 'view values' to use percent values' Triggering Screen Reference: Display of Incomes by Articles pop-up of the Reports screen Correct Behavior: The appearance of the report should be changed to 'use percent values' | H4: Buggy Behavior: the application crashes Triggering GUI Interactions: checks View values, checks Use percent values, and taps OK Triggering Screen Reference: On the Display of Incomes by Articles pop-up of the Reports screen Correct Behavior: The appearance of the report should be changed to use percent values. | I4: Correct | J4: Correct | K4: Correct | L4: Correct
A6: 10 | B6: Material Files | C6: bugscribe_mutli-candidate_transitions_and_screen_descriptions | D6: HC_LP | E6: On the FTP server screen, stopping it and closing the app makes the server restart, even though it should stay stopped. | G6: Buggy Behavior: the server restarts automatically Triggering GUI Interaction: stops the FTP server and then closes the app Triggering Screen Reference: FTP server screen Correct Behavior: The FTP server should remain stopped | H6: Buggy Behavior: the FTP server restarts automatically after stopping it and closing the app Triggering GUI Interactions: the user turns off the FTP server switch and then closes the app Triggering Screen Reference: On the FTP server screen Correct Behavior: The FTP server should stay stopped after stopping it and closing the app. | I6: Correct | J6: Correct | K6: Correct | L6: Correct
A8: 10 | B8: Material Files | C8: bugscribe_mutli-candidate_transitions_and_screen_descriptions | D8: LC_LP | E8: It restarts on its own. | G8: Buggy Behavior: the server restarts automatically Triggering GUI Interaction: stops the FTP server and then closes the app Triggering Screen Reference: FTP server screen Correct Behavior: The FTP server should remain stopped | H8: Buggy Behavior: the FTP server is restarting on its own Triggering GUI Interactions: turns the server on, turns it off, leaves the FTP server screen, and then swipes the app away from Recents Triggering Screen Reference: On the FTP server screen Correct Behavior: The FTP server should remain off after the user toggles it off and leaves the FTP server screen, and it should not restart automatically on its own. | I8: Correct | J8: Correct | K8: Correct | L8: Correct
A10: 135 | B10: Wikimedia Commons | C10: bugscribe_mutli-candidate_transitions_and_screen_descriptions | D10: HC_HP | E10: Open App, swipe left four times, tap YES, tap Skip, tap YES, open the navigation drawer, select Explore, tap a picture, swipe up twice, tap a category, and tap Parent Categories to reach the Category screen in the Parent Categories tab; clicking the Parent Categories tab results in a blank page, but the Parent Categories of the current category should be displayed. | F10: Title: Parent Categories tab opens a blank page on the category details screen Observed Behavior: On the Category Details screen in the Parent Categories tab, if the user taps the PARENT CATEGORIES tab, a blank page is shown. Expected Behavior: The Parent Categories of the current category should be displayed. | G10: Buggy Behavior: see a blank page Triggering GUI Interaction: clicks the Parent Categories tab Triggering Screen Reference: Category screen, Parent Categories tab Correct Behavior: The Parent Categories of the current category should be displayed | H10: Buggy Behavior: a blank page is shown Triggering GUI Interactions: taps the PARENT CATEGORIES tab Triggering Screen Reference: On the Category Details screen in the Parent Categories tab Correct Behavior: The Parent Categories of the current category should be displayed | I10: Correct | J10: Correct | K10: Correct | L10: Correct
A12: 135 | B12: Wikimedia Commons | C12: bugscribe_mutli-candidate_transitions_and_screen_descriptions | D12: LC_HP | E12: The Parent Categories of the current category should be displayed. | G12: Buggy Behavior: see a blank page Triggering GUI Interaction: clicks the Parent Categories tab Triggering Screen Reference: Category screen, Parent Categories tab Correct Behavior: The Parent Categories of the current category should be displayed | H12: Buggy Behavior: the parent categories of the current category are not displayed Triggering GUI Interactions: taps the "PARENT CATEGORIES" tab Triggering Screen Reference: On the category details screen for "Focus stacking images of insects," Correct Behavior: The parent categories of the current category should be displayed. | I12: Correct | J12: Correct | K12: Incomplete | L12: Correct
A14: 135 | B14: Wikimedia Commons | C14: bugscribe_mutli-candidate_transitions_and_screen_descriptions | D14: MC_HP | E14: Clicking the Parent Categories tab results in a blank page, but the Parent Categories of the current category should be displayed. | G14: Buggy Behavior: see a blank page Triggering GUI Interaction: clicks the Parent Categories tab Triggering Screen Reference: Category screen, Parent Categories tab Correct Behavior: The Parent Categories of the current category should be displayed | H14: Buggy Behavior: the app results in a blank page Triggering GUI Interactions: taps the PARENT CATEGORIES tab Triggering Screen Reference: On the Category Details screen Correct Behavior: The Parent Categories of the current category should be displayed. | I14: Correct | J14: Correct | K14: Incomplete | L14: Correct
A16: 2 | B16: Family Finance | C16: bugscribe_mutli-candidate_transitions_and_screen_descriptions | D16: HC_HP | E16: On Display of Incomes by Articles pop-up of the Reports screen changing the report appearance from 'view values' to 'use percent values' causes the application to crash, but the appearance of the report should be changed to 'use percent values'. I took these steps: Open the app, tap Allow, select Report, choose Incomes By Articles or Expenses By Articles, tap View, check 'view values', check 'use percent values', and tap OK. | G16: Buggy Behavior: the application crashes Triggering GUI Interaction: changes the appearance of the report from 'view values' to use percent values' Triggering Screen Reference: Display of Incomes by Articles pop-up of the Reports screen Correct Behavior: The appearance of the report should be changed to 'use percent values' | H16: Buggy Behavior: the application crashes Triggering GUI Interactions: checks View values, checks Use percent values, and taps OK Triggering Screen Reference: On the Display of Incomes by Articles dialog of the Reports screen Correct Behavior: The appearance of the report should be changed to use percent values. | I16: Correct | J16: Correct | K16: Correct | L16: Correct
A18: 2 | B18: Family Finance | C18: bugscribe_mutli-candidate_transitions_and_screen_descriptions | D18: MC_MP | E18: Changing the report appearance from 'view values' to 'use percent values' results in the application crashing. | G18: Buggy Behavior: the application crashes Triggering GUI Interaction: changes the appearance of the report from 'view values' to use percent values' Triggering Screen Reference: Display of Incomes by Articles pop-up of the Reports screen Correct Behavior: The appearance of the report should be changed to 'use percent values' | H18: Buggy Behavior: the application crashes Triggering GUI Interactions: the user taps the "Use percent values" checkbox Triggering Screen Reference: On the Display of Incomes by Articles dialog Correct Behavior: The application should change the report appearance to use percent values without crashing. | I18: Correct | J18: Correct | K18: Correct | L18: Correct

Sheet Summary
A1: agent_version | B1: s2r_cs_count | C1: s2r_ms_count | D1: s2r_es_count | E1: average_s2r_precision | F1: average_s2r_recall | G1: average_s2r_f1 | H1: info_correct_count | I1: info_incomplete_count | J1: info_ambiguous_count | K1: info_missing_count | L1: info_incorrect_count | M1: average_total_tokens_consumed_per_conv | N1: average_wall_clock_seconds_per_conv | O1: average_turn_processing_seconds_per_conv | P1: average_conversation_turns
A2: bugscribe_mutli-candidate_transitions_and_screen_descriptions | B2: =COUNTIF('S2R Review'!$K:$K,"CS") | C2: =SUM('S2R Review'!$O:$O)-B2 | D2: =COUNTIF('S2R Review'!$K:$K,"ES") | E2: =IFERROR(SUM('S2R Review'!$L$2:$L$1048576)/COUNTIF('S2R Review'!$L$2:$L$1048576,"<>"),"") | F2: =IFERROR(SUM('S2R Review'!$M$2:$M$1048576)/COUNTIF('S2R Review'!$M$2:$M$1048576,"<>"),"") | G2: =IFERROR(SUM('S2R Review'!$N$2:$N$1048576)/COUNTIF('S2R Review'!$N$2:$N$1048576,"<>"),"") | H2: =COUNTIF('Info Elements Review'!$I:$I,"Correct")+COUNTIF('Info Elements Review'!$J:$J,"Correct")+COUNTIF('Info Elements Review'!$K:$K,"Correct")+COUNTIF('Info Elements Review'!$L:$L,"Correct") | I2: =COUNTIF('Info Elements Review'!$I:$I,"Incomplete")+COUNTIF('Info Elements Review'!$J:$J,"Incomplete")+COUNTIF('Info Elements Review'!$K:$K,"Incomplete")+COUNTIF('Info Elements Review'!$L:$L,"Incomplete") | J2: =COUNTIF('Info Elements Review'!$I:$I,"Ambiguous")+COUNTIF('Info Elements Review'!$J:$J,"Ambiguous")+COUNTIF('Info Elements Review'!$K:$K,"Ambiguous")+COUNTIF('Info Elements Review'!$L:$L,"Ambiguous") | K2: =COUNTIF('Info Elements Review'!$I:$I,"Missing")+COUNTIF('Info Elements Review'!$J:$J,"Missing")+COUNTIF('Info Elements Review'!$K:$K,"Missing")+COUNTIF('Info Elements Review'!$L:$L,"Missing") | L2: =COUNTIF('Info Elements Review'!$I:$I,"Incorrect")+COUNTIF('Info Elements Review'!$J:$J,"Incorrect")+COUNTIF('Info Elements Review'!$K:$K,"Incorrect")+COUNTIF('Info Elements Review'!$L:$L,"Incorrect") | M2: 71972.111 | N2: 28.520764 | O2: 28.520764 | P2: 1.3333333
